{"url": "https://api.github.com/repos/rust-lang/rust/issues/18158", "repository_url": "https://api.github.com/repos/rust-lang/rust", "labels_url": "https://api.github.com/repos/rust-lang/rust/issues/18158/labels{/name}", "comments_url": "https://api.github.com/repos/rust-lang/rust/issues/18158/comments", "events_url": "https://api.github.com/repos/rust-lang/rust/issues/18158/events", "html_url": "https://github.com/rust-lang/rust/issues/18158", "id": 46207475, "node_id": "MDU6SXNzdWU0NjIwNzQ3NQ==", "number": 18158, "title": "Test output shows non-existing path", "user": {"login": "cakebaker", "id": 26196, "node_id": "MDQ6VXNlcjI2MTk2", "avatar_url": "https://avatars.githubusercontent.com/u/26196?v=4", "gravatar_id": "", "url": "https://api.github.com/users/cakebaker", "html_url": "https://github.com/cakebaker", "followers_url": "https://api.github.com/users/cakebaker/followers", "following_url": "https://api.github.com/users/cakebaker/following{/other_user}", "gists_url": "https://api.github.com/users/cakebaker/gists{/gist_id}", "starred_url": "https://api.github.com/users/cakebaker/starred{/owner}{/repo}", "subscriptions_url": "https://api.github.com/users/cakebaker/subscriptions", "organizations_url": "https://api.github.com/users/cakebaker/orgs", "repos_url": "https://api.github.com/users/cakebaker/repos", "events_url": "https://api.github.com/users/cakebaker/events{/privacy}", "received_events_url": "https://api.github.com/users/cakebaker/received_events", "type": "User", "site_admin": false}, "labels": [], "state": "closed", "locked": false, "assignee": null, "assignees": [], "milestone": null, "comments": 2, "created_at": "2014-10-19T14:52:40Z", "updated_at": "2015-10-27T15:12:16Z", "closed_at": "2015-10-27T15:12:16Z", "author_association": "CONTRIBUTOR", "active_lock_reason": null, "body": "I'm following the [Writing Tests](http://doc.rust-lang.org/guide.html#writing-tests) section in the guide. When I run <code>cargo test</code> for the first test (that fails as expected), the last line of the output contains a path that doesn't exist on my system:\n\n```\ntask '<main>' failed at 'Some tests failed', /home/rustbuild/src/rust-buildbot/slave/nightly-linux/build/src/libtest/lib.rs:243\n```\n\nI also don't know what the purpose of this line should be, to me as a newbie it looks redundant to:\n\n```\ntest result: FAILED. 0 passed; 1 failed; 0 ignored; 0 measured\n```\n", "closed_by": {"login": "steveklabnik", "id": 27786, "node_id": "MDQ6VXNlcjI3Nzg2", "avatar_url": "https://avatars.githubusercontent.com/u/27786?v=4", "gravatar_id": "", "url": "https://api.github.com/users/steveklabnik", "html_url": "https://github.com/steveklabnik", "followers_url": "https://api.github.com/users/steveklabnik/followers", "following_url": "https://api.github.com/users/steveklabnik/following{/other_user}", "gists_url": "https://api.github.com/users/steveklabnik/gists{/gist_id}", "starred_url": "https://api.github.com/users/steveklabnik/starred{/owner}{/repo}", "subscriptions_url": "https://api.github.com/users/steveklabnik/subscriptions", "organizations_url": "https://api.github.com/users/steveklabnik/orgs", "repos_url": "https://api.github.com/users/steveklabnik/repos", "events_url": "https://api.github.com/users/steveklabnik/events{/privacy}", "received_events_url": "https://api.github.com/users/steveklabnik/received_events", "type": "User", "site_admin": false}, "reactions": {"url": "https://api.github.com/repos/rust-lang/rust/issues/18158/reactions", "total_count": 0, "+1": 0, "-1": 0, "laugh": 0, "hooray": 0, "confused": 0, "heart": 0, "rocket": 0, "eyes": 0}, "timeline_url": "https://api.github.com/repos/rust-lang/rust/issues/18158/timeline", "performed_via_github_app": null, "state_reason": "completed"}